<?xml version="1.0" ?>
<robot name="three_js_robot">

    <!-- Base Link -->
    <link name="base_link">
        <visual>
            <geometry>
                <box size="1.4 1 1.4"/>
            </geometry>
            <material name="blue"/>
        </visual>
    </link>

    <!-- Shoulder Link and Joint -->
    <link name="shoulder_link">
        <visual>
            <geometry>
                <box size="0.25 3 0.5"/>
            </geometry>
            <material name="red"/>
        </visual>
    </link>
    <joint name="shoulder_joint" type="revolute">
        <parent link="base_link"/>
        <child link="shoulder_link"/>
        <axis xyz="0 0 1"/>
        <origin xyz="0 0.5 0" rpy="0 0 0"/>
        <limit lower="-3.14159" upper="3.14159" effort="100" velocity="1"/>
    </joint>

    <!-- Elbow Link and Joint -->
    <link name="elbow_link">
        <visual>
        <geometry>
            <box size="0.25 1.5 0.25"/>
        </geometry>
        <material name="blue"/>
        </visual>
    </link>
    <joint name="elbow_joint" type="revolute">
        <parent link="shoulder_link"/>
        <child link="elbow_link"/>
        <axis xyz="0 0 1"/>
        <origin xyz="0 1.5 0" rpy="0 0 0"/>
        <limit lower="-3.14159" upper="3.14159" effort="100" velocity="1"/>
    </joint>

    <!-- Wrist Link and Joint -->
    <link name="wrist_link">
        <visual>
        <geometry>
            <box size="0.25 1 0.25"/>
        </geometry>
        <material name="green"/>
        </visual>
    </link>
    <joint name="wrist_joint" type="revolute">
        <parent link="elbow_link"/>
        <child link="wrist_link"/>
        <axis xyz="0 1 0"/>
        <origin xyz="0 0.75 0" rpy="0 0 0"/>
        <limit lower="-3.14159" upper="3.14159" effort="100" velocity="1"/>
    </joint>

    <!-- Wrist2 Link and Joint -->
    <link name="wrist2_link">
        <visual>
        <geometry>
            <box size="0.25 0.5 0.25"/>
        </geometry>
        <material name="red"/>
        </visual>
    </link>
    <joint name="wrist2_joint" type="revolute">
        <parent link="wrist_link"/>
        <child link="wrist2_link"/>
        <axis xyz="0 0 1"/>
        <origin xyz="0 0.25 0" rpy="0 0 0"/>
        <limit lower="-3.14159" upper="3.14159" effort="100" velocity="1"/>
    </joint>

    <!-- Wrist3 Link and Joint -->
    <link name="wrist3_link">
        <visual>
        <geometry>
            <box size="0.25 0.5 0.25"/>
        </geometry>
        <material name="blue"/>
        </visual>
    </link>
    <joint name="wrist3_joint" type="revolute">
        <parent link="wrist2_link"/>
        <child link="wrist3_link"/>
        <axis xyz="0 1 0"/>
        <origin xyz="0 0.25 0" rpy="0 0 0"/>
        <limit lower="-3.14159" upper="3.14159" effort="100" velocity="1"/>
    </joint>

    <!-- Gripper Link and Joint -->
    <link name="gripper_link">
        <visual>
        <geometry>
            <!-- Adjust the size based on your gripper's design -->
            <box size="0.25 0.25 0.25"/>
        </geometry>
        <material name="green"/>
        </visual>
    </link>
    <joint name="gripper_joint" type="prismatic"> <!-- Assuming a prismatic joint for the gripper -->
        <parent link="wrist3_link"/>
        <child link="gripper_link"/>
        <axis xyz="1 0 0"/>
        <origin xyz="0 0.25 0" rpy="0 0 0"/>
        <limit lower="0" upper="0.1" effort="100" velocity="1"/> <!-- Adjust these limits based on your gripper's range -->
    </joint>

    <!-- Additional material definitions as needed -->
    <material name="green">
        <color rgba="0 1 0 1"/>
    </material>

    <!-- Material Properties -->
    <material name="red">
        <color rgba="1 0 0 1"/>
    </material>
    <material name="blue">
        <color rgba="0 0 1 1"/>
    </material>
    <!-- Additional materials as per your color scheme -->

</robot>
